Workbook

Sheet Growth Analysis
A1: Territory | B1: Jan - Mar (Q1) | J1: April - Jun (Q2)
B2: DN | E2: Collection | J2: Target
B3: 55197.687 | C3: 36479.581 | D3: =IFERROR((C3-B3)/B3,100%) -> -0.33911033 | E3: 1.6087766e+09 | F3: 1.7847808e+09 | G3: =IFERROR((F3-E3)/E3,100%) -> 0.10940249 | H3: Total | J3: 38000 | K3: 24600 | L3: 27000 | M3: =SUM(J3:L3) -> 89600
B4: 2025 | C4: 2026 | D4: Growth | E4: 2025 | F4: 2026 | G4: Growth | H4: Contribution 2026 | I4: Contribution 2025 | J4: Apr | K4: May | L4: Jun | M4: total
A5: Debiganj | B5: 0 | C5: 218.61453 | D5: =IFERROR((C5-B5)/B5,100%) -> 1 | E5: 0 | F5: 10882606 | G5: =IFERROR((F5-E5)/E5,100%) -> 1 | H5: =F5/$F$3 -> 0.0060974467 | I5: =E5/$E$3 -> 0 | J5: =$J$3*H5 -> 231.70297 | K5: =$K$3*H5 -> 149.99719 | L5: =$L$3*H5 -> 164.63106 | M5: =SUM(J5:L5) -> 546.33122
A6: Boda | B6: 863.54776 | C6: 161.43507 | D6: =IFERROR((C6-B6)/B6,100%) -> -0.813056 | E6: 29967600 | F6: 6965953.7 | G6: =IFERROR((F6-E6)/E6,100%) -> -0.7675505 | H6: =F6/$F$3 -> 0.0039029744 | I6: =E6/$E$3 -> 0.018627571 | J6: =$J$3*H6 -> 148.31303 | K6: =$K$3*H6 -> 96.01317 | L6: =$L$3*H6 -> 105.38031 | M6: =SUM(J6:L6) -> 349.7065
A7: Tetulia | B7: 0 | C7: 86.578039 | D7: =IFERROR((C7-B7)/B7,100%) -> 1 | E7: 0 | F7: 4737540.8 | G7: =IFERROR((F7-E7)/E7,100%) -> 1 | H7: =F7/$F$3 -> 0.0026544104 | I7: =E7/$E$3 -> 0 | J7: =$J$3*H7 -> 100.8676 | K7: =$K$3*H7 -> 65.298497 | L7: =$L$3*H7 -> 71.669082 | M7: =SUM(J7:L7) -> 237.83518
A8: Panchagarh Sadar | B8: 382.58925 | C8: 166.62421 | D8: =IFERROR((C8-B8)/B8,100%) -> -0.56448277 | E8: 6759276.8 | F8: 8571373 | G8: =IFERROR((F8-E8)/E8,100%) -> 0.26809025 | H8: =F8/$F$3 -> 0.0048024794 | I8: =E8/$E$3 -> 0.0042015012 | J8: =$J$3*H8 -> 182.49422 | K8: =$K$3*H8 -> 118.14099 | L8: =$L$3*H8 -> 129.66694 | M8: =SUM(J8:L8) -> 430.30216
A9: Atwari | B9: 375.10041 | C9: 111.141 | D9: =IFERROR((C9-B9)/B9,100%) -> -0.70370333 | E9: 15849772 | F9: 8071774.4 | G9: =IFERROR((F9-E9)/E9,100%) -> -0.49073246 | H9: =F9/$F$3 -> 0.0045225579 | I9: =E9/$E$3 -> 0.009852065 | J9: =$J$3*H9 -> 171.8572 | K9: =$K$3*H9 -> 111.25492 | L9: =$L$3*H9 -> 122.10906 | M9: =SUM(J9:L9) -> 405.22118
A10: Baliadangi | B10: 0 | C10: 86.868626 | D10: =IFERROR((C10-B10)/B10,100%) -> 1 | E10: 405501 | F10: 5615183.4 | G10: =IFERROR((F10-E10)/E10,100%) -> 12.84752 | H10: =F10/$F$3 -> 0.0031461474 | I10: =E10/$E$3 -> 0.0002520555 | J10: =$J$3*H10 -> 119.5536 | K10: =$K$3*H10 -> 77.395225 | L10: =$L$3*H10 -> 84.945979 | M10: =SUM(J10:L10) -> 281.8948
A11: Ruhia | B11: 0 | C11: 93.15537 | D11: =IFERROR((C11-B11)/B11,100%) -> 1 | E11: 0 | F11: 7678287.9 | G11: =IFERROR((F11-E11)/E11,100%) -> 1 | H11: =F11/$F$3 -> 0.0043020902 | I11: =E11/$E$3 -> 0 | J11: =$J$3*H11 -> 163.47943 | K11: =$K$3*H11 -> 105.83142 | L11: =$L$3*H11 -> 116.15643 | M11: =SUM(J11:L11) -> 385.46728
A12: Panchagarh Area | B12: 1621.2374 | C12: 924.41685 | D12: =IFERROR((C12-B12)/B12,100%) -> -0.42980785 | E12: 52982150 | F12: 52522719 | G12: =IFERROR((F12-E12)/E12,100%) -> -0.0086714267 | H12: =F12/$F$3 -> 0.029428106 | I12: =E12/$E$3 -> 0.032933192 | J12: =$J$3*H12 -> 1118.268 | K12: =$K$3*H12 -> 723.93142 | L12: =$L$3*H12 -> 794.55887 | M12: =SUM(J12:L12) -> 2636.7583
A13: Pirganj_Thakurgaon | B13: 0 | C13: 77.639814 | D13: =IFERROR((C13-B13)/B13,100%) -> 1 | E13: 812738.04 | F13: 6165818.3 | G13: =IFERROR((F13-E13)/E13,100%) -> 6.5864769 | H13: =F13/$F$3 -> 0.0034546642 | I13: =E13/$E$3 -> 0.00050519011 | J13: =$J$3*H13 -> 131.27724 | K13: =$K$3*H13 -> 84.98474 | L13: =$L$3*H13 -> 93.275934 | M13: =SUM(J13:L13) -> 309.53791
A14: Ranisankail | B14: 0 | C14: 118.16876 | D14: =IFERROR((C14-B14)/B14,100%) -> 1 | E14: 0 | F14: 8376159.9 | G14: =IFERROR((F14-E14)/E14,100%) -> 1 | H14: =F14/$F$3 -> 0.0046931029 | I14: =E14/$E$3 -> 0 | J14: =$J$3*H14 -> 178.33791 | K14: =$K$3*H14 -> 115.45033 | L14: =$L$3*H14 -> 126.71378 | M14: =SUM(J14:L14) -> 420.50202
A15: Thakurgaon Sadar | B15: 515.9315 | C15: 119.80646 | D15: =IFERROR((C15-B15)/B15,100%) -> -0.76778611 | E15: 25461030 | F15: 9484805.3 | G15: =IFERROR((F15-E15)/E15,100%) -> -0.62747755 | H15: =F15/$F$3 -> 0.005314269 | I15: =E15/$E$3 -> 0.01582633 | J15: =$J$3*H15 -> 201.94222 | K15: =$K$3*H15 -> 130.73102 | L15: =$L$3*H15 -> 143.48526 | M15: =SUM(J15:L15) -> 476.15851
A16: Birganj | B16: 0 | C16: 113.72498 | D16: =IFERROR((C16-B16)/B16,100%) -> 1 | E16: 203245.2 | F16: 4186426.7 | G16: =IFERROR((F16-E16)/E16,100%) -> 19.597912 | H16: =F16/$F$3 -> 0.0023456251 | I16: =E16/$E$3 -> 0.00012633525 | J16: =$J$3*H16 -> 89.133754 | K16: =$K$3*H16 -> 57.702378 | L16: =$L$3*H16 -> 63.331878 | M16: =SUM(J16:L16) -> 210.16801
... A339: National Total | B339: 55197.687 | C339: 36479.581 | D339: =IFERROR((C339-B339)/B339,100%) -> -0.33911033 | E339: 1.6087766e+09 | F339: 1.7847808e+09 | G339: =IFERROR((F339-E339)/E339,100%) -> 0.10940249 | H339: =F339/$F$3 -> 1 | I339: =E339/$E$3 -> 1 | J339: =$J$3*H339 -> 38000 | K339: =$K$3*H339 -> 24600 | L339: =$L$3*H339 -> 27000 | M339: =SUM(J339:L339) -> 89600

Sheet April - Jun (Q2) Collection
A1: Territory | B1: Jan - Mar (Q1) | K1: April - Jun (Q2 - 2026) | O1: April - Jun (Q2 - 2026)
B2: DN | E2: Collection | K2: Target Projected - TP | O2: Target on 2026 Contribution - TOC | T2: April - Jun (Q2 - 2025)
B3: 55198 | C3: 36480 | D3: =IFERROR((C3-B3)/B3,100%) -> -0.33910649 | E3: 1608776622 | F3: 1784780789 | G3: =IFERROR((F3-E3)/E3,100%) -> 0.10940249 | H3: Total | K3: 1.3799709e+09 | L3: 8.2798252e+08 | M3: 8.8318135e+08 | N3: 3.0911347e+09 | O3: =37500*36000 -> 1350000000 | P3: =22500*36000 -> 810000000 | Q3: =24000*36000 -> 864000000 | R3: =SUM(O3:Q3) -> 3024000000 | S3: Variance TOC - TP | T3: 1.0835386e+09 | U3: 7.8039267e+08 | V3: 8.1403813e+08 | W3: 2.6779694e+09 | X3: =IFERROR((R3/W3-1),100%) -> 0.12921382
B4: 2025 | C4: 2026 | D4: Growth | E4: 2025 | F4: 2026 | G4: Growth | H4: Contribution 2026 | I4: Contribution 2025 | K4: Apr | L4: May | M4: Jun | N4: Total | O4: Apr | P4: May | Q4: Jun | R4: Total | T4: Apr | U4: May | V4: Jun | W4: Total | X4: Growth
A5: Debiganj | B5: =VLOOKUP($A5,'Growth Analysis'!A:G,2,FALSE) -> 0 | C5: =VLOOKUP(A5,'Growth Analysis'!A:G,4,FALSE) -> 1 | D5: =IFERROR((C5-B5)/B5,100%) -> 1 | E5: =VLOOKUP($A5,'Growth Analysis'!$A:$G,5,FALSE) -> 0 | F5: =VLOOKUP($A5,'Growth Analysis'!$A:$G,6,FALSE) -> 10882606 | G5: =IFERROR((F5-E5)/E5,100%) -> 1 | H5: =F5/$F$3 -> 0.0060974467 | I5: =E5/$E$3 -> 0 | J5: 0 | K5: =VLOOKUP($A5,[1]Notes!$A:$G,3,FALSE) -> 8177777.8 | L5: =VLOOKUP($A5,[1]Notes!$A:$G,5,FALSE) -> 4906666.7 | M5: =VLOOKUP($A5,[1]Notes!$A:$G,7,FALSE) -> 5233777.8 | N5: =SUM(K5:M5) -> 18318222 | O5: =$O$3*H5 -> 8231553 | P5: =$P$3*H5 -> 4938931.8 | Q5: =$Q$3*H5 -> 5268193.9 | R5: =SUM(O5:Q5) -> 18438679 | S5: =N5/R5-1 -> -0.0065328184 | T5: =VLOOKUP($A5,'[2]All month (2)'!$E:$Y,8,FALSE) -> 0 | U5: =VLOOKUP($A5,'[2]All month (2)'!$E:$Y,14,FALSE) -> 9902304 | V5: =VLOOKUP($A5,'[2]All month (2)'!$E:$Y,20,FALSE) -> 13348800 | W5: =SUM(T5:V5) -> 23251104 | X5: =IFERROR((R5-W5)/W5,100%) -> -0.2069762
A6: Boda | B6: =VLOOKUP($A6,'Growth Analysis'!A:G,2,FALSE) -> 863.54776 | C6: =VLOOKUP(A6,'Growth Analysis'!A:G,4,FALSE) -> -0.813056 | D6: =IFERROR((C6-B6)/B6,100%) -> -1.0009415 | E6: =VLOOKUP($A6,'Growth Analysis'!$A:$G,5,FALSE) -> 29967600 | F6: =VLOOKUP($A6,'Growth Analysis'!$A:$G,6,FALSE) -> 6965953.7 | G6: =IFERROR((F6-E6)/E6,100%) -> -0.7675505 | H6: =F6/$F$3 -> 0.0039029744 | I6: =E6/$E$3 -> 0.018627571 | J6: 846.61545 | K6: =VLOOKUP($A6,[1]Notes!$A:$G,3,FALSE) -> 8031746 | L6: =VLOOKUP($A6,[1]Notes!$A:$G,5,FALSE) -> 4819047.6 | M6: =VLOOKUP($A6,[1]Notes!$A:$G,7,FALSE) -> 5140317.5 | N6: =SUM(K6:M6) -> 17991111 | O6: =$O$3*H6 -> 5269015.4 | P6: =$P$3*H6 -> 3161409.3 | Q6: =$Q$3*H6 -> 3372169.9 | R6: =SUM(O6:Q6) -> 11802595 | S6: =R6/N6-1 -> -0.34397634 | T6: =VLOOKUP($A6,'[2]All month (2)'!$E:$Y,8,FALSE) -> 31100000 | U6: =VLOOKUP($A6,'[2]All month (2)'!$E:$Y,14,FALSE) -> 10727496 | V6: =VLOOKUP($A6,'[2]All month (2)'!$E:$Y,20,FALSE) -> 14461200 | W6: =SUM(T6:V6) -> 56288696 | X6: =IFERROR((R6-W6)/W6,100%) -> -0.79032034
A7: Tetulia | B7: =VLOOKUP($A7,'Growth Analysis'!A:G,2,FALSE) -> 0 | C7: =VLOOKUP(A7,'Growth Analysis'!A:G,4,FALSE) -> 1 | D7: =IFERROR((C7-B7)/B7,100%) -> 1 | E7: =VLOOKUP($A7,'Growth Analysis'!$A:$G,5,FALSE) -> 0 | F7: =VLOOKUP($A7,'Growth Analysis'!$A:$G,6,FALSE) -> 4737540.8 | G7: =IFERROR((F7-E7)/E7,100%) -> 1 | H7: =F7/$F$3 -> 0.0026544104 | I7: =E7/$E$3 -> 0 | J7: 0 | K7: =VLOOKUP($A7,[1]Notes!$A:$G,3,FALSE) -> 2920634.9 | L7: =VLOOKUP($A7,[1]Notes!$A:$G,5,FALSE) -> 1752381 | M7: =VLOOKUP($A7,[1]Notes!$A:$G,7,FALSE) -> 1869206.3 | N7: =SUM(K7:M7) -> 6542222.2 | O7: =$O$3*H7 -> 3583454.1 | P7: =$P$3*H7 -> 2150072.5 | Q7: =$Q$3*H7 -> 2293410.6 | R7: =SUM(O7:Q7) -> 8026937.2 | S7: =R7/N7-1 -> 0.22694352 | T7: =VLOOKUP($A7,'[2]All month (2)'!$E:$Y,8,FALSE) -> 0 | U7: =VLOOKUP($A7,'[2]All month (2)'!$E:$Y,14,FALSE) -> 2911637.7 | V7: =VLOOKUP($A7,'[2]All month (2)'!$E:$Y,20,FALSE) -> 2524353.7 | W7: =SUM(T7:V7) -> 5435991.4 | X7: =IFERROR((R7-W7)/W7,100%) -> 0.47662801
A8: Panchagarh Sadar | B8: =VLOOKUP($A8,'Growth Analysis'!A:G,2,FALSE) -> 382.58925 | C8: =VLOOKUP(A8,'Growth Analysis'!A:G,4,FALSE) -> -0.56448277 | D8: =IFERROR((C8-B8)/B8,100%) -> -1.0014754 | E8: =VLOOKUP($A8,'Growth Analysis'!$A:$G,5,FALSE) -> 6759276.8 | F8: =VLOOKUP($A8,'Growth Analysis'!$A:$G,6,FALSE) -> 8571373 | G8: =IFERROR((F8-E8)/E8,100%) -> 0.26809025 | H8: =F8/$F$3 -> 0.0048024794 | I8: =E8/$E$3 -> 0.0042015012 | J8: 375.0875 | K8: =VLOOKUP($A8,[1]Notes!$A:$G,3,FALSE) -> 7082539.7 | L8: =VLOOKUP($A8,[1]Notes!$A:$G,5,FALSE) -> 4249523.8 | M8: =VLOOKUP($A8,[1]Notes!$A:$G,7,FALSE) -> 4532825.4 | N8: =SUM(K8:M8) -> 15864889 | O8: =$O$3*H8 -> 6483347.2 | P8: =$P$3*H8 -> 3890008.3 | Q8: =$Q$3*H8 -> 4149342.2 | R8: =SUM(O8:Q8) -> 14522698 | S8: =R8/N8-1 -> -0.084601353 | T8: =VLOOKUP($A8,'[2]All month (2)'!$E:$Y,8,FALSE) -> 4704269 | U8: =VLOOKUP($A8,'[2]All month (2)'!$E:$Y,14,FALSE) -> 7128492.3 | V8: =VLOOKUP($A8,'[2]All month (2)'!$E:$Y,20,FALSE) -> 6180314.3 | W8: =SUM(T8:V8) -> 18013076 | X8: =IFERROR((R8-W8)/W8,100%) -> -0.19376912
A9: Atwari | B9: =VLOOKUP($A9,'Growth Analysis'!A:G,2,FALSE) -> 375.10041 | C9: =VLOOKUP(A9,'Growth Analysis'!A:G,4,FALSE) -> -0.70370333 | D9: =IFERROR((C9-B9)/B9,100%) -> -1.001876 | E9: =VLOOKUP($A9,'Growth Analysis'!$A:$G,5,FALSE) -> 15849772 | F9: =VLOOKUP($A9,'Growth Analysis'!$A:$G,6,FALSE) -> 8071774.4 | G9: =IFERROR((F9-E9)/E9,100%) -> -0.49073246 | H9: =F9/$F$3 -> 0.0045225579 | I9: =E9/$E$3 -> 0.009852065 | J9: 367.7455 | K9: =VLOOKUP($A9,[1]Notes!$A:$G,3,FALSE) -> 5330158.7 | L9: =VLOOKUP($A9,[1]Notes!$A:$G,5,FALSE) -> 3198095.2 | M9: =VLOOKUP($A9,[1]Notes!$A:$G,7,FALSE) -> 3411301.6 | N9: =SUM(K9:M9) -> 11939556 | O9: =$O$3*H9 -> 6105453.1 | P9: =$P$3*H9 -> 3663271.9 | Q9: =$Q$3*H9 -> 3907490 | R9: =SUM(O9:Q9) -> 13676215 | S9: =R9/N9-1 -> 0.14545428 | T9: =VLOOKUP($A9,'[2]All month (2)'!$E:$Y,8,FALSE) -> 10000000 | U9: =VLOOKUP($A9,'[2]All month (2)'!$E:$Y,14,FALSE) -> 3844032.5 | V9: =VLOOKUP($A9,'[2]All month (2)'!$E:$Y,20,FALSE) -> 4758415.1 | W9: =SUM(T9:V9) -> 18602448 | X9: =IFERROR((R9-W9)/W9,100%) -> -0.26481637
A10: Baliadangi | B10: =VLOOKUP($A10,'Growth Analysis'!A:G,2,FALSE) -> 0 | C10: =VLOOKUP(A10,'Growth Analysis'!A:G,4,FALSE) -> 1 | D10: =IFERROR((C10-B10)/B10,100%) -> 1 | E10: =VLOOKUP($A10,'Growth Analysis'!$A:$G,5,FALSE) -> 405501 | F10: =VLOOKUP($A10,'Growth Analysis'!$A:$G,6,FALSE) -> 5615183.4 | G10: =IFERROR((F10-E10)/E10,100%) -> 12.84752 | H10: =F10/$F$3 -> 0.0031461474 | I10: =E10/$E$3 -> 0.0002520555 | J10: 0 | K10: =VLOOKUP($A10,[1]Notes!$A:$G,3,FALSE) -> 3869841.3 | L10: =VLOOKUP($A10,[1]Notes!$A:$G,5,FALSE) -> 2321904.8 | M10: =VLOOKUP($A10,[1]Notes!$A:$G,7,FALSE) -> 2476698.4 | N10: =SUM(K10:M10) -> 8668444.4 | O10: =$O$3*H10 -> 4247298.9 | P10: =$P$3*H10 -> 2548379.4 | Q10: =$Q$3*H10 -> 2718271.3 | R10: =SUM(O10:Q10) -> 9513949.6 | S10: =R10/N10-1 -> 0.097538281 | T10: =VLOOKUP($A10,'[2]All month (2)'!$E:$Y,8,FALSE) -> 0 | U10: =VLOOKUP($A10,'[2]All month (2)'!$E:$Y,14,FALSE) -> 2630127.5 | V10: =VLOOKUP($A10,'[2]All month (2)'!$E:$Y,20,FALSE) -> 3255757.7 | W10: =SUM(T10:V10) -> 5885885.2 | X10: =IFERROR((R10-W10)/W10,100%) -> 0.61640081
A11: Ruhia | B11: =VLOOKUP($A11,'Growth Analysis'!A:G,2,FALSE) -> 0 | C11: =VLOOKUP(A11,'Growth Analysis'!A:G,4,FALSE) -> 1 | D11: =IFERROR((C11-B11)/B11,100%) -> 1 | E11: =VLOOKUP($A11,'Growth Analysis'!$A:$G,5,FALSE) -> 0 | F11: =VLOOKUP($A11,'Growth Analysis'!$A:$G,6,FALSE) -> 7678287.9 | G11: =IFERROR((F11-E11)/E11,100%) -> 1 | H11: =F11/$F$3 -> 0.0043020902 | I11: =E11/$E$3 -> 0 | J11: 0 | K11: =VLOOKUP($A11,[1]Notes!$A:$G,3,FALSE) -> 5987301.6 | L11: =VLOOKUP($A11,[1]Notes!$A:$G,5,FALSE) -> 3592381 | M11: =VLOOKUP($A11,[1]Notes!$A:$G,7,FALSE) -> 3831873 | N11: =SUM(K11:M11) -> 13411556 | O11: =$O$3*H11 -> 5807821.7 | P11: =$P$3*H11 -> 3484693 | Q11: =$Q$3*H11 -> 3717005.9 | R11: =SUM(O11:Q11) -> 13009521 | S11: =R11/N11-1 -> -0.029976752 | T11: =VLOOKUP($A11,'[2]All month (2)'!$E:$Y,8,FALSE) -> 0 | U11: =VLOOKUP($A11,'[2]All month (2)'!$E:$Y,14,FALSE) -> 3641715 | V11: =VLOOKUP($A11,'[2]All month (2)'!$E:$Y,20,FALSE) -> 4507972.2 | W11: =SUM(T11:V11) -> 8149687.2 | X11: =IFERROR((R11-W11)/W11,100%) -> 0.59632147
A12: Panchagarh Area | B12: =SUM(B5:B11) -> 1621.2374 | C12: =SUM(C5:C11) -> 1.9187579 | D12: =IFERROR((C12-B12)/B12,100%) -> -0.99881649 | E12: =SUM(E5:E11) -> 52982150 | F12: =SUM(F5:F11) -> 52522719 | G12: =IFERROR((F12-E12)/E12,100%) -> -0.0086714267 | H12: =F12/$F$3 -> 0.029428106 | I12: =E12/$E$3 -> 0.032933192 | J12: =SUM(J5:J11) -> 1589.4484 | K12: =SUM(K5:K11) -> 41400000 | L12: =SUM(L5:L11) -> 24840000 | M12: =SUM(M5:M11) -> 26496000 | N12: =SUM(K12:M12) -> 92736000 | O12: =$O$3*H12 -> 39727944 | P12: =$P$3*H12 -> 23836766 | Q12: =$Q$3*H12 -> 25425884 | R12: =SUM(O12:Q12) -> 88990594 | T12: =SUM(T5:T11) -> 45804269 | U12: =SUM(U5:U11) -> 40785805 | V12: =SUM(V5:V11) -> 49036813 | W12: =SUM(W5:W11) -> 135626887 | X12: =IFERROR((R12-W12)/W12,100%) -> -0.34385729
A13: Pirganj_Thakurgaon | B13: =VLOOKUP($A13,'Growth Analysis'!A:G,2,FALSE) -> 0 | C13: =VLOOKUP(A13,'Growth Analysis'!A:G,4,FALSE) -> 1 | D13: =IFERROR((C13-B13)/B13,100%) -> 1 | E13: =VLOOKUP($A13,'Growth Analysis'!$A:$G,5,FALSE) -> 812738.04 | F13: =VLOOKUP($A13,'Growth Analysis'!$A:$G,6,FALSE) -> 6165818.3 | G13: =IFERROR((F13-E13)/E13,100%) -> 6.5864769 | H13: =F13/$F$3 -> 0.0034546642 | I13: =E13/$E$3 -> 0.00050519011 | J13: 0 | K13: =VLOOKUP($A13,[1]Notes!$A:$G,3,FALSE) -> 4968000 | L13: =VLOOKUP($A13,[1]Notes!$A:$G,5,FALSE) -> 2980800 | M13: =VLOOKUP($A13,[1]Notes!$A:$G,7,FALSE) -> 3179520 | N13: =SUM(K13:M13) -> 11128320 | O13: =$O$3*H13 -> 4663796.7 | P13: =$P$3*H13 -> 2798278 | Q13: =$Q$3*H13 -> 2984829.9 | R13: =SUM(O13:Q13) -> 10446905 | S13: =R13/N13-1 -> -0.061232548 | T13: =VLOOKUP($A13,'[2]All month (2)'!$E:$Y,8,FALSE) -> 0 | U13: =VLOOKUP($A13,'[2]All month (2)'!$E:$Y,14,FALSE) -> 3190535 | V13: =VLOOKUP($A13,'[2]All month (2)'!$E:$Y,20,FALSE) -> 3002979 | W13: =SUM(T13:V13) -> 6193514 | X13: =IFERROR((R13-W13)/W13,100%) -> 0.68674916
A14: Ranisankail | B14: =VLOOKUP($A14,'Growth Analysis'!A:G,2,FALSE) -> 0 | C14: =VLOOKUP(A14,'Growth Analysis'!A:G,4,FALSE) -> 1 | D14: =IFERROR((C14-B14)/B14,100%) -> 1 | E14: =VLOOKUP($A14,'Growth Analysis'!$A:$G,5,FALSE) -> 0 | F14: =VLOOKUP($A14,'Growth Analysis'!$A:$G,6,FALSE) -> 8376159.9 | G14: =IFERROR((F14-E14)/E14,100%) -> 1 | H14: =F14/$F$3 -> 0.0046931029 | I14: =E14/$E$3 -> 0 | J14: 0 | K14: =VLOOKUP($A14,[1]Notes!$A:$G,3,FALSE) -> 7617600 | L14: =VLOOKUP($A14,[1]Notes!$A:$G,5,FALSE) -> 4570560 | M14: =VLOOKUP($A14,[1]Notes!$A:$G,7,FALSE) -> 4875264 | N14: =SUM(K14:M14) -> 17063424 | O14: =$O$3*H14 -> 6335688.9 | P14: =$P$3*H14 -> 3801413.4 | Q14: =$Q$3*H14 -> 4054840.9 | R14: =SUM(O14:Q14) -> 14191943 | S14: =R14/N14-1 -> -0.1682828 | T14: =VLOOKUP($A14,'[2]All month (2)'!$E:$Y,8,FALSE) -> 0 | U14: =VLOOKUP($A14,'[2]All month (2)'!$E:$Y,14,FALSE) -> 3630608.9 | V14: =VLOOKUP($A14,'[2]All month (2)'!$E:$Y,20,FALSE) -> 3417183 | W14: =SUM(T14:V14) -> 7047791.8 | X14: =IFERROR((R14-W14)/W14,100%) -> 1.0136723
A15: Thakurgaon Sadar | B15: =VLOOKUP($A15,'Growth Analysis'!A:G,2,FALSE) -> 515.9315 | C15: =VLOOKUP(A15,'Growth Analysis'!A:G,4,FALSE) -> -0.76778611 | D15: =IFERROR((C15-B15)/B15,100%) -> -1.0014882 | E15: =VLOOKUP($A15,'Growth Analysis'!$A:$G,5,FALSE) -> 25461030 | F15: =VLOOKUP($A15,'Growth Analysis'!$A:$G,6,FALSE) -> 9484805.3 | G15: =IFERROR((F15-E15)/E15,100%) -> -0.62747755 | H15: =F15/$F$3 -> 0.005314269 | I15: =E15/$E$3 -> 0.01582633 | J15: 505.8152 | K15: =VLOOKUP($A15,[1]Notes!$A:$G,3,FALSE) -> 7948800 | L15: =VLOOKUP($A15,[1]Notes!$A:$G,5,FALSE) -> 4769280 | M15: =VLOOKUP($A15,[1]Notes!$A:$G,7,FALSE) -> 5087232 | N15: =SUM(K15:M15) -> 17805312 | O15: =$O$3*H15 -> 7174263.2 | P15: =$P$3*H15 -> 4304557.9 | Q15: =$Q$3*H15 -> 4591528.4 | R15: =SUM(O15:Q15) -> 16070350 | S15: =R15/N15-1 -> -0.097440721 | T15: =VLOOKUP($A15,'[2]All month (2)'!$E:$Y,8,FALSE) -> 25170081 | U15: =VLOOKUP($A15,'[2]All month (2)'!$E:$Y,14,FALSE) -> 4180701.1 | V15: =VLOOKUP($A15,'[2]All month (2)'!$E:$Y,20,FALSE) -> 3934938 | W15: =SUM(T15:V15) -> 33285720 | X15: =IFERROR((R15-W15)/W15,100%) -> -0.51719988
A16: Birganj | B16: =VLOOKUP($A16,'Growth Analysis'!A:G,2,FALSE) -> 0 | C16: =VLOOKUP(A16,'Growth Analysis'!A:G,4,FALSE) -> 1 | D16: =IFERROR((C16-B16)/B16,100%) -> 1 | E16: =VLOOKUP($A16,'Growth Analysis'!$A:$G,5,FALSE) -> 203245.2 | F16: =VLOOKUP($A16,'Growth Analysis'!$A:$G,6,FALSE) -> 4186426.7 | G16: =IFERROR((F16-E16)/E16,100%) -> 19.597912 | H16: =F16/$F$3 -> 0.0023456251 | I16: =E16/$E$3 -> 0.00012633525 | J16: 0 | K16: =VLOOKUP($A16,[1]Notes!$A:$G,3,FALSE) -> 4968000 | L16: =VLOOKUP($A16,[1]Notes!$A:$G,5,FALSE) -> 2980800 | M16: =VLOOKUP($A16,[1]Notes!$A:$G,7,FALSE) -> 3179520 | N16: =SUM(K16:M16) -> 11128320 | O16: =$O$3*H16 -> 3166593.9 | P16: =$P$3*H16 -> 1899956.3 | Q16: =$Q$3*H16 -> 2026620.1 | R16: =SUM(O16:Q16) -> 7093170.4 | S16: =R16/N16-1 -> -0.36260187 | T16: =VLOOKUP($A16,'[2]All month (2)'!$E:$Y,8,FALSE) -> 22600017 | U16: =VLOOKUP($A16,'[2]All month (2)'!$E:$Y,14,FALSE) -> 3614710.8 | V16: =VLOOKUP($A16,'[2]All month (2)'!$E:$Y,20,FALSE) -> 2335287.4 | W16: =SUM(T16:V16) -> 28550015 | X16: =IFERROR((R16-W16)/W16,100%) -> -0.75155283
A17: Khansama | B17: =VLOOKUP($A17,'Growth Analysis'!A:G,2,FALSE) -> 0 | C17: =VLOOKUP(A17,'Growth Analysis'!A:G,4,FALSE) -> 1 | D17: =IFERROR((C17-B17)/B17,100%) -> 1 | E17: =VLOOKUP($A17,'Growth Analysis'!$A:$G,5,FALSE) -> 0 | F17: =VLOOKUP($A17,'Growth Analysis'!$A:$G,6,FALSE) -> 3429066.9 | G17: =IFERROR((F17-E17)/E17,100%) -> 1 | H17: =F17/$F$3 -> 0.0019212818 | I17: =E17/$E$3 -> 0 | J17: 0 | K17: =VLOOKUP($A17,[1]Notes!$A:$G,3,FALSE) -> 4968000 | L17: =VLOOKUP($A17,[1]Notes!$A:$G,5,FALSE) -> 2980800 | M17: =VLOOKUP($A17,[1]Notes!$A:$G,7,FALSE) -> 3179520 | N17: =SUM(K17:M17) -> 11128320 | O17: =$O$3*H17 -> 2593730.5 | P17: =$P$3*H17 -> 1556238.3 | Q17: =$Q$3*H17 -> 1659987.5 | R17: =SUM(O17:Q17) -> 5809956.3 | S17: =R17/N17-1 -> -0.47791255 | T17: =VLOOKUP($A17,'[2]All month (2)'!$E:$Y,8,FALSE) -> 0 | U17: =VLOOKUP($A17,'[2]All month (2)'!$E:$Y,14,FALSE) -> 3313484.9 | V17: =VLOOKUP($A17,'[2]All month (2)'!$E:$Y,20,FALSE) -> 2140680.1 | W17: =SUM(T17:V17) -> 5454165 | X17: =IFERROR((R17-W17)/W17,100%) -> 0.06523295
A18: Kaharole | B18: =VLOOKUP($A18,'Growth Analysis'!A:G,2,FALSE) -> 0 | C18: =VLOOKUP(A18,'Growth Analysis'!A:G,4,FALSE) -> 1 | D18: =IFERROR((C18-B18)/B18,100%) -> 1 | E18: =VLOOKUP($A18,'Growth Analysis'!$A:$G,5,FALSE) -> 0 | F18: =VLOOKUP($A18,'Growth Analysis'!$A:$G,6,FALSE) -> 5136695.5 | G18: =IFERROR((F18-E18)/E18,100%) -> 1 | H18: =F18/$F$3 -> 0.002878054 | I18: =E18/$E$3 -> 0 | J18: 0 | K18: =VLOOKUP($A18,[1]Notes!$A:$G,3,FALSE) -> 4968000 | L18: =VLOOKUP($A18,[1]Notes!$A:$G,5,FALSE) -> 2980800 | M18: =VLOOKUP($A18,[1]Notes!$A:$G,7,FALSE) -> 3179520 | N18: =SUM(K18:M18) -> 11128320 | O18: =$O$3*H18 -> 3885372.9 | P18: =$P$3*H18 -> 2331223.8 | Q18: =$Q$3*H18 -> 2486638.7 | R18: =SUM(O18:Q18) -> 8703235.4 | S18: =R18/N18-1 -> -0.2179201 | T18: =VLOOKUP($A18,'[2]All month (2)'!$E:$Y,8,FALSE) -> 0 | U18: =VLOOKUP($A18,'[2]All month (2)'!$E:$Y,14,FALSE) -> 4066549.6 | V18: =VLOOKUP($A18,'[2]All month (2)'!$E:$Y,20,FALSE) -> 2627198.3 | W18: =SUM(T18:V18) -> 6693747.9 | X18: =IFERROR((R18-W18)/W18,100%) -> 0.30020364
A19: Bochaganj | B19: =VLOOKUP($A19,'Growth Analysis'!A:G,2,FALSE) -> 0 | C19: =VLOOKUP(A19,'Growth Analysis'!A:G,4,FALSE) -> 1 | D19: =IFERROR((C19-B19)/B19,100%) -> 1 | E19: =VLOOKUP($A19,'Growth Analysis'!$A:$G,5,FALSE) -> 391680 | F19: =VLOOKUP($A19,'Growth Analysis'!$A:$G,6,FALSE) -> 5416272.8 | G19: =IFERROR((F19-E19)/E19,100%) -> 12.828311 | H19: =F19/$F$3 -> 0.0030346992 | I19: =E19/$E$3 -> 0.0002434645 | J19: 0 | K19: =VLOOKUP($A19,[1]Notes!$A:$G,3,FALSE) -> 5961600 | L19: =VLOOKUP($A19,[1]Notes!$A:$G,5,FALSE) -> 3576960 | M19: =VLOOKUP($A19,[1]Notes!$A:$G,7,FALSE) -> 3815424 | N19: =SUM(K19:M19) -> 13353984 | O19: =$O$3*H19 -> 4096843.9 | P19: =$P$3*H19 -> 2458106.3 | Q19: =$Q$3*H19 -> 2621980.1 | R19: =SUM(O19:Q19) -> 9176930.2 | S19: =R19/N19-1 -> -0.31279458 | T19: =VLOOKUP($A19,'[2]All month (2)'!$E:$Y,8,FALSE) -> 0 | U19: =VLOOKUP($A19,'[2]All month (2)'!$E:$Y,14,FALSE) -> 4066549.6 | V19: =VLOOKUP($A19,'[2]All month (2)'!$E:$Y,20,FALSE) -> 2627198.3 | W19: =SUM(T19:V19) -> 6693747.9 | X19: =IFERROR((R19-W19)/W19,100%) -> 0.37097039
A20: Thakurgaon Area | B20: =SUM(B13:B19) -> 515.9315 | C20: =SUM(C13:C19) -> 5.2322139 | D20: =IFERROR((C20-B20)/B20,100%) -> -0.9898587 | E20: =SUM(E13:E19) -> 26868693 | F20: =SUM(F13:F19) -> 42195245 | G20: =IFERROR((F20-E20)/E20,100%) -> 0.57042418 | H20: =F20/$F$3 -> 0.023641696 | I20: =E20/$E$3 -> 0.01670132 | J20: =SUM(J13:J19) -> 505.8152 | K20: =SUM(K13:K19) -> 41400000 | L20: =SUM(L13:L19) -> 24840000 | M20: =SUM(M13:M19) -> 26496000 | N20: =SUM(K20:M20) -> 92736000 | O20: 368 | P20: =$P$3*H20 -> 19149774 | Q20: =$Q$3*H20 -> 20426426 | R20: =SUM(O20:Q20) -> 39576568 | T20: =SUM(T13:T19) -> 47770098 | U20: =SUM(U13:U19) -> 26063140 | V20: =SUM(V13:V19) -> 20085464 | W20: =SUM(W13:W19) -> 93918702 | X20: =IFERROR((R20-W20)/W20,100%) -> -0.57860823
A21: Domar | B21: =VLOOKUP($A21,'Growth Analysis'!A:G,2,FALSE) -> 185.65683 | C21: =VLOOKUP(A21,'Growth Analysis'!A:G,4,FALSE) -> -0.9317822 | D21: =IFERROR((C21-B21)/B21,100%) -> -1.0050188 | E21: =VLOOKUP($A21,'Growth Analysis'!$A:$G,5,FALSE) -> 6910500 | F21: =VLOOKUP($A21,'Growth Analysis'!$A:$G,6,FALSE) -> 1155000 | G21: =IFERROR((F21-E21)/E21,100%) -> -0.83286303 | H21: =F21/$F$3 -> 0.0006471383 | I21: =E21/$E$3 -> 0.0042955 | J21: 182.0165 | K21: =VLOOKUP($A21,[1]Notes!$A:$G,3,FALSE) -> 4475675.7 | L21: =VLOOKUP($A21,[1]Notes!$A:$G,5,FALSE) -> 2685405.4 | M21: =VLOOKUP($A21,[1]Notes!$A:$G,7,FALSE) -> 2864432.4 | N21: =SUM(K21:M21) -> 10025514 | O21: =$O$3*H21 -> 873636.7 | P21: =$P$3*H21 -> 524182.02 | Q21: =$Q$3*H21 -> 559127.49 | R21: =SUM(O21:Q21) -> 1956946.2 | S21: =R21/N21-1 -> -0.80480339 | T21: =VLOOKUP($A21,'[2]All month (2)'!$E:$Y,8,FALSE) -> 3514000 | U21: =VLOOKUP($A21,'[2]All month (2)'!$E:$Y,14,FALSE) -> 1791000 | V21: =VLOOKUP($A21,'[2]All month (2)'!$E:$Y,20,FALSE) -> 2279000 | W21: =SUM(T21:V21) -> 7584000 | X21: =IFERROR((R21-W21)/W21,100%) -> -0.74196384
A22: Jaldhaka | B22: =VLOOKUP($A22,'Growth Analysis'!A:G,2,FALSE) -> 0 | C22: =VLOOKUP(A22,'Growth Analysis'!A:G,4,FALSE) -> 1 | D22: =IFERROR((C22-B22)/B22,100%) -> 1 | E22: =VLOOKUP($A22,'Growth Analysis'!$A:$G,5,FALSE) -> 0 | F22: =VLOOKUP($A22,'Growth Analysis'!$A:$G,6,FALSE) -> 4006543.8 | G22: =IFERROR((F22-E22)/E22,100%) -> 1 | H22: =F22/$F$3 -> 0.002244838 | I22: =E22/$E$3 -> 0 | J22: 0 | K22: =VLOOKUP($A22,[1]Notes!$A:$G,3,FALSE) -> 5967567.6 | L22: =VLOOKUP($A22,[1]Notes!$A:$G,5,FALSE) -> 3580540.5 | M22: =VLOOKUP($A22,[1]Notes!$A:$G,7,FALSE) -> 3819243.2 | N22: =SUM(K22:M22) -> 13367351 | O22: =$O$3*H22 -> 3030531.3 | P22: =$P$3*H22 -> 1818318.8 | Q22: =$Q$3*H22 -> 1939540.1 | R22: =SUM(O22:Q22) -> 6788390.2 | S22: =R22/N22-1 -> -0.4921664 | T22: =VLOOKUP($A22,'[2]All month (2)'!$E:$Y,8,FALSE) -> 0 | U22: =VLOOKUP($A22,'[2]All month (2)'!$E:$Y,14,FALSE) -> 3322557.1 | V22: =VLOOKUP($A22,'[2]All month (2)'!$E:$Y,20,FALSE) -> 2274085.4 | W22: =SUM(T22:V22) -> 5596642.6 | X22: =IFERROR((R22-W22)/W22,100%) -> 0.21293974
A23: Nilphamari Sadar | B23: =VLOOKUP($A23,'Growth Analysis'!A:G,2,FALSE) -> 1370.4014 | C23: =VLOOKUP(A23,'Growth Analysis'!A:G,4,FALSE) -> -0.90647687 | D23: =IFERROR((C23-B23)/B23,100%) -> -1.0006615 | E23: =VLOOKUP($A23,'Growth Analysis'!$A:$G,5,FALSE) -> 21299339 | F23: =VLOOKUP($A23,'Growth Analysis'!$A:$G,6,FALSE) -> 3415849 | G23: =IFERROR((F23-E23)/E23,100%) -> -0.83962653 | H23: =F23/$F$3 -> 0.0019138759 | I23: =E23/$E$3 -> 0.013239463 | J23: 1343.5307 | K23: =VLOOKUP($A23,[1]Notes!$A:$G,3,FALSE) -> 5221621.6 | L23: =VLOOKUP($A23,[1]Notes!$A:$G,5,FALSE) -> 3132973 | M23: =VLOOKUP($A23,[1]Notes!$A:$G,7,FALSE) -> 3341837.8 | N23: =SUM(K23:M23) -> 11696432 | O23: =$O$3*H23 -> 2583732.5 | P23: =$P$3*H23 -> 1550239.5 | Q23: =$Q$3*H23 -> 1653588.8 | R23: =SUM(O23:Q23) -> 5787560.9 | S23: =R23/N23-1 -> -0.5051858 | T23: =VLOOKUP($A23,'[2]All month (2)'!$E:$Y,8,FALSE) -> 20975628 | U23: =VLOOKUP($A23,'[2]All month (2)'!$E:$Y,14,FALSE) -> 6437454.4 | V23: =VLOOKUP($A23,'[2]All month (2)'!$E:$Y,20,FALSE) -> 4406040.5 | W23: =SUM(T23:V23) -> 31819123 | X23: =IFERROR((R23-W23)/W23,100%) -> -0.81811061
A24: Sayedpur | B24: =VLOOKUP($A24,'Growth Analysis'!A:G,2,FALSE) -> 0 | C24: =VLOOKUP(A24,'Growth Analysis'!A:G,4,FALSE) -> 1 | D24: =IFERROR((C24-B24)/B24,100%) -> 1 | E24: =VLOOKUP($A24,'Growth Analysis'!$A:$G,5,FALSE) -> 0 | F24: =VLOOKUP($A24,'Growth Analysis'!$A:$G,6,FALSE) -> 2354295.2 | G24: =IFERROR((F24-E24)/E24,100%) -> 1 | H24: =F24/$F$3 -> 0.0013190949 | I24: =E24/$E$3 -> 0 | J24: 0 | K24: =VLOOKUP($A24,[1]Notes!$A:$G,3,FALSE) -> 3729729.7 | L24: =VLOOKUP($A24,[1]Notes!$A:$G,5,FALSE) -> 2237837.8 | M24: =VLOOKUP($A24,[1]Notes!$A:$G,7,FALSE) -> 2387027 | N24: =SUM(K24:M24) -> 8354594.6 | O24: =$O$3*H24 -> 1780778.1 | P24: =$P$3*H24 -> 1068466.9 | Q24: =$Q$3*H24 -> 1139698 | R24: =SUM(O24:Q24) -> 3988943 | S24: =R24/N24-1 -> -0.522545 | T24: =VLOOKUP($A24,'[2]All month (2)'!$E:$Y,8,FALSE) -> 0 | U24: =VLOOKUP($A24,'[2]All month (2)'!$E:$Y,14,FALSE) -> 4153196.4 | V24: =VLOOKUP($A24,'[2]All month (2)'!$E:$Y,20,FALSE) -> 2842606.8 | W24: =SUM(T24:V24) -> 6995803.2 | X24: =IFERROR((R24-W24)/W24,100%) -> -0.42980915
A25: Dimla | B25: =VLOOKUP($A25,'Growth Analysis'!A:G,2,FALSE) -> 0 | C25: =VLOOKUP(A25,'Growth Analysis'!A:G,4,FALSE) -> 1 | D25: =IFERROR((C25-B25)/B25,100%) -> 1 | E25: =VLOOKUP($A25,'Growth Analysis'!$A:$G,5,FALSE) -> 0 | F25: =VLOOKUP($A25,'Growth Analysis'!$A:$G,6,FALSE) -> 4006543.8 | G25: =IFERROR((F25-E25)/E25,100%) -> 1 | H25: =F25/$F$3 -> 0.002244838 | I25: =E25/$E$3 -> 0 | J25: 0 | K25: =VLOOKUP($A25,[1]Notes!$A:$G,3,FALSE) -> 5967567.6 | L25: =VLOOKUP($A25,[1]Notes!$A:$G,5,FALSE) -> 3580540.5 | M25: =VLOOKUP($A25,[1]Notes!$A:$G,7,FALSE) -> 3819243.2 | N25: =SUM(K25:M25) -> 13367351 | O25: =$O$3*H25 -> 3030531.3 | P25: =$P$3*H25 -> 1818318.8 | Q25: =$Q$3*H25 -> 1939540.1 | R25: =SUM(O25:Q25) -> 6788390.2 | S25: =R25/N25-1 -> -0.4921664 | T25: =VLOOKUP($A25,'[2]All month (2)'!$E:$Y,8,FALSE) -> 0 | U25: =VLOOKUP($A25,'[2]All month (2)'!$E:$Y,14,FALSE) -> 4360856.2 | V25: =VLOOKUP($A25,'[2]All month (2)'!$E:$Y,20,FALSE) -> 2984737.1 | W25: =SUM(T25:V25) -> 7345593.4 | X25: =IFERROR((R25-W25)/W25,100%) -> -0.075855433
A26: Kishoreganj_Nilphamari | B26: =VLOOKUP($A26,'Growth Analysis'!A:G,2,FALSE) -> 0 | C26: =VLOOKUP(A26,'Growth Analysis'!A:G,4,FALSE) -> 1 | D26: =IFERROR((C26-B26)/B26,100%) -> 1 | E26: =VLOOKUP($A26,'Growth Analysis'!$A:$G,5,FALSE) -> 0 | F26: =VLOOKUP($A26,'Growth Analysis'!$A:$G,6,FALSE) -> 1412577.1 | G26: =IFERROR((F26-E26)/E26,100%) -> 1 | H26: =F26/$F$3 -> 0.00079145693 | I26: =E26/$E$3 -> 0 | J26: 0 | K26: =VLOOKUP($A26,[1]Notes!$A:$G,3,FALSE) -> 2237837.8 | L26: =VLOOKUP($A26,[1]Notes!$A:$G,5,FALSE) -> 1342702.7 | M26: =VLOOKUP($A26,[1]Notes!$A:$G,7,FALSE) -> 1432216.2 | N26: =SUM(K26:M26) -> 5012756.8 | O26: =$O$3*H26 -> 1068466.9 | P26: =$P$3*H26 -> 641080.12 | Q26: =$Q$3*H26 -> 683818.79 | R26: =SUM(O26:Q26) -> 2393365.8 | S26: =R26/N26-1 -> -0.522545 | T26: =VLOOKUP($A26,'[2]All month (2)'!$E:$Y,8,FALSE) -> 0 | U26: =VLOOKUP($A26,'[2]All month (2)'!$E:$Y,14,FALSE) -> 2491917.8 | V26: =VLOOKUP($A26,'[2]All month (2)'!$E:$Y,20,FALSE) -> 1705564.1 | W26: =SUM(T26:V26) -> 4197481.9 | X26: =IFERROR((R26-W26)/W26,100%) -> -0.42980915
A27: Nilphamari Area | B27: =SUM(B21:B26) -> 1556.0582 | C27: =SUM(C21:C26) -> 2.1617409 | D27: =IFERROR((C27-B27)/B27,100%) -> -0.99861076 | E27: =SUM(E21:E26) -> 28209839 | F27: =SUM(F21:F26) -> 16350809 | G27: =IFERROR((F27-E27)/E27,100%) -> -0.42038631 | H27: =F27/$F$3 -> 0.0091612421 | I27: =E27/$E$3 -> 0.017534963 | J27: =SUM(J21:J26) -> 1525.5472 | K27: =SUM(K21:K26) -> 27600000 | L27: =SUM(L21:L26) -> 16560000 | M27: =SUM(M21:M26) -> 17664000 | N27: =SUM(K27:M27) -> 61824000 | O27: =$O$3*H27 -> 12367677 | P27: =$P$3*H27 -> 7420606.1 | Q27: =$Q$3*H27 -> 7915313.2 | R27: =SUM(O27:Q27) -> 27703596 | T27: =SUM(T21:T26) -> 24489628 | U27: =SUM(U21:U26) -> 22556982 | V27: =SUM(V21:V26) -> 16492034 | W27: =SUM(W21:W26) -> 63538644 | X27: =IFERROR((R27-W27)/W27,100%) -> -0.56398824
A28: Birol | B28: =VLOOKUP($A28,'Growth Analysis'!A:G,2,FALSE) -> 0 | C28: =VLOOKUP(A28,'Growth Analysis'!A:G,4,FALSE) -> 1 | D28: =IFERROR((C28-B28)/B28,100%) -> 1 | E28: =VLOOKUP($A28,'Growth Analysis'!$A:$G,5,FALSE) -> 0 | F28: =VLOOKUP($A28,'Growth Analysis'!$A:$G,6,FALSE) -> 15630806 | G28: =IFERROR((F28-E28)/E28,100%) -> 1 | H28: =F28/$F$3 -> 0.0087578295 | I28: =E28/$E$3 -> 0 | J28: 0 | K28: =VLOOKUP($A28,[1]Notes!$A:$G,3,FALSE) -> 10466508 | L28: =VLOOKUP($A28,[1]Notes!$A:$G,5,FALSE) -> 6279904.6 | M28: =VLOOKUP($A28,[1]Notes!$A:$G,7,FALSE) -> 6698564.9 | N28: =SUM(K28:M28) -> 23444977 | O28: =$O$3*H28 -> 11823070 | P28: =$P$3*H28 -> 7093841.9 | Q28: =$Q$3*H28 -> 7566764.7 | R28: =SUM(O28:Q28) -> 26483676 | S28: =R28/N28-1 -> 0.12960982 | T28: =VLOOKUP($A28,'[2]All month (2)'!$E:$Y,8,FALSE) -> 0 | U28: =VLOOKUP($A28,'[2]All month (2)'!$E:$Y,14,FALSE) -> 5661173.5 | V28: =VLOOKUP($A28,'[2]All month (2)'!$E:$Y,20,FALSE) -> 9222132.4 | W28: =SUM(T28:V28) -> 14883306 | X28: =IFERROR((R28-W28)/W28,100%) -> 0.77942163
A29: Chirirbandar | B29: =VLOOKUP($A29,'Growth Analysis'!A:G,2,FALSE) -> 0 | C29: =VLOOKUP(A29,'Growth Analysis'!A:G,4,FALSE) -> 1 | D29: =IFERROR((C29-B29)/B29,100%) -> 1 | E29: =VLOOKUP($A29,'Growth Analysis'!$A:$G,5,FALSE) -> 357000 | F29: =VLOOKUP($A29,'Growth Analysis'!$A:$G,6,FALSE) -> 16050806 | G29: =IFERROR((F29-E29)/E29,100%) -> 43.96024 | H29: =F29/$F$3 -> 0.0089931525 | I29: =E29/$E$3 -> 0.00022190775 | J29: 0 | K29: =VLOOKUP($A29,[1]Notes!$A:$G,3,FALSE) -> 10466508 | L29: =VLOOKUP($A29,[1]Notes!$A:$G,5,FALSE) -> 6279904.6 | M29: =VLOOKUP($A29,[1]Notes!$A:$G,7,FALSE) -> 6698564.9 | N29: =SUM(K29:M29) -> 23444977 | O29: =$O$3*H29 -> 12140756 | P29: =$P$3*H29 -> 7284453.5 | Q29: =$Q$3*H29 -> 7770083.8 | R29: =SUM(O29:Q29) -> 27195293 | S29: =R29/N29-1 -> 0.15996245 | T29: =VLOOKUP($A29,'[2]All month (2)'!$E:$Y,8,FALSE) -> 50000 | U29: =VLOOKUP($A29,'[2]All month (2)'!$E:$Y,14,FALSE) -> 4924390 | V29: =VLOOKUP($A29,'[2]All month (2)'!$E:$Y,20,FALSE) -> 8020876 | W29: =SUM(T29:V29) -> 12995266 | X29: =IFERROR((R29-W29)/W29,100%) -> 1.0927077
A30: Dinajpur Sadar | B30: =VLOOKUP($A30,'Growth Analysis'!A:G,2,FALSE) -> 2222.1154 | C30: =VLOOKUP(A30,'Growth Analysis'!A:G,4,FALSE) -> -0.88216842 | D30: =IFERROR((C30-B30)/B30,100%) -> -1.000397 | E30: =VLOOKUP($A30,'Growth Analysis'!$A:$G,5,FALSE) -> 59488914 | F30: =VLOOKUP($A30,'Growth Analysis'!$A:$G,6,FALSE) -> 11595445 | G30: =IFERROR((F30-E30)/E30,100%) -> -0.80508226 | H30: =F30/$F$3 -> 0.0064968454 | I30: =E30/$E$3 -> 0.036977734 | J30: 2178.5445 | K30: =VLOOKUP($A30,[1]Notes!$A:$G,3,FALSE) -> 9419856.9 | L30: =VLOOKUP($A30,[1]Notes!$A:$G,5,FALSE) -> 5651914.1 | M30: =VLOOKUP($A30,[1]Notes!$A:$G,7,FALSE) -> 6028708.4 | N30: =SUM(K30:M30) -> 21100479 | O30: =$O$3*H30 -> 8770741.3 | P30: =$P$3*H30 -> 5262444.8 | Q30: =$Q$3*H30 -> 5613274.4 | R30: =SUM(O30:Q30) -> 19646461 | S30: =N30/R30-1 -> 0.074009207 | T30: =VLOOKUP($A30,'[2]All month (2)'!$E:$Y,8,FALSE) -> 45832080 | U30: =VLOOKUP($A30,'[2]All month (2)'!$E:$Y,14,FALSE) -> 5648673.5 | V30: =VLOOKUP($A30,'[2]All month (2)'!$E:$Y,20,FALSE) -> 9209632.4 | W30: =SUM(T30:V30) -> 60690386 | X30: =IFERROR((R30-W30)/W30,100%) -> -0.67628381
A31: Parbatipur | B31: =VLOOKUP($A31,'Growth Analysis'!A:G,2,FALSE) -> 61.5111 | C31: =VLOOKUP(A31,'Growth Analysis'!A:G,4,FALSE) -> 2.6198196 | D31: =IFERROR((C31-B31)/B31,100%) -> -0.95740899 | E31: =VLOOKUP($A31,'Growth Analysis'!$A:$G,5,FALSE) -> 2027760 | F31: =VLOOKUP($A31,'Growth Analysis'!$A:$G,6,FALSE) -> 9794030.2 | G31: =IFERROR((F31-E31)/E31,100%) -> 3.8299751 | H31: =F31/$F$3 -> 0.0054875256 | I31: =E31/$E$3 -> 0.001260436 | J31: 60.305 | K31: =VLOOKUP($A31,[1]Notes!$A:$G,3,FALSE) -> 6279904.6 | L31: =VLOOKUP($A31,[1]Notes!$A:$G,5,FALSE) -> 3767942.8 | M31: =VLOOKUP($A31,[1]Notes!$A:$G,7,FALSE) -> 4019138.9 | N31: =SUM(K31:M31) -> 14066986 | O31: =$O$3*H31 -> 7408159.5 | P31: =$P$3*H31 -> 4444895.7 | Q31: =$Q$3*H31 -> 4741222.1 | R31: =SUM(O31:Q31) -> 16594277 | S31: =R31/N31-1 -> 0.17966116 | T31: =VLOOKUP($A31,'[2]All month (2)'!$E:$Y,8,FALSE) -> 0 | U31: =VLOOKUP($A31,'[2]All month (2)'!$E:$Y,14,FALSE) -> 3942012 | V31: =VLOOKUP($A31,'[2]All month (2)'!$E:$Y,20,FALSE) -> 6419200.8 | W31: =SUM(T31:V31) -> 10361213 | X31: =IFERROR((R31-W31)/W31,100%) -> 0.60157673
A32: Fulbari_Dinajpur | B32: =VLOOKUP($A32,'Growth Analysis'!A:G,2,FALSE) -> 0 | C32: =VLOOKUP(A32,'Growth Analysis'!A:G,4,FALSE) -> 1 | D32: =IFERROR((C32-B32)/B32,100%) -> 1 | E32: =VLOOKUP($A32,'Growth Analysis'!$A:$G,5,FALSE) -> 0 | F32: =VLOOKUP($A32,'Growth Analysis'!$A:$G,6,FALSE) -> 9447741.3 | G32: =IFERROR((F32-E32)/E32,100%) -> 1 | H32: =F32/$F$3 -> 0.0052935023 | I32: =E32/$E$3 -> 0 | J32: 0 | K32: =VLOOKUP($A32,[1]Notes!$A:$G,3,FALSE) -> 6279904.6 | L32: =VLOOKUP($A32,[1]Notes!$A:$G,5,FALSE) -> 3767942.8 | M32: =VLOOKUP($A32,[1]Notes!$A:$G,7,FALSE) -> 4019138.9 | N32: =SUM(K32:M32) -> 14066986 | O32: =$O$3*H32 -> 7146228.2 | P32: =$P$3*H32 -> 4287736.9 | Q32: =$Q$3*H32 -> 4573586 | R32: =SUM(O32:Q32) -> 16007551 | S32: =R32/N32-1 -> 0.13795171 | T32: =VLOOKUP($A32,'[2]All month (2)'!$E:$Y,8,FALSE) -> 0 | U32: =VLOOKUP($A32,'[2]All month (2)'!$E:$Y,14,FALSE) -> 4420701 | V32: =VLOOKUP($A32,'[2]All month (2)'!$E:$Y,20,FALSE) -> 7207538.4 | W32: =SUM(T32:V32) -> 11628239 | X32: =IFERROR((R32-W32)/W32,100%) -> 0.37661004
A33: Hakimpur | B33: =VLOOKUP($A33,'Growth Analysis'!A:G,2,FALSE) -> 0 | C33: =VLOOKUP(A33,'Growth Analysis'!A:G,4,FALSE) -> 1 | D33: =IFERROR((C33-B33)/B33,100%) -> 1 | E33: =VLOOKUP($A33,'Growth Analysis'!$A:$G,5,FALSE) -> 1261740 | F33: =VLOOKUP($A33,'Growth Analysis'!$A:$G,6,FALSE) -> 2373149.5 | G33: =IFERROR((F33-E33)/E33,100%) -> 0.8808546 | H33: =F33/$F$3 -> 0.0013296588 | I33: =E33/$E$3 -> 0.00078428539 | J33: 0 | K33: =VLOOKUP($A33,[1]Notes!$A:$G,3,FALSE) -> 3139952.3 | L33: =VLOOKUP($A33,[1]Notes!$A:$G,5,FALSE) -> 1883971.4 | M33: =VLOOKUP($A33,[1]Notes!$A:$G,7,FALSE) -> 2009569.5 | N33: =SUM(K33:M33) -> 7033493.2 | O33: =$O$3*H33 -> 1795039.4 | P33: =$P$3*H33 -> 1077023.6 | Q33: =$Q$3*H33 -> 1148825.2 | R33: =SUM(O33:Q33) -> 4020888.2 | S33: =R33/N33-1 -> -0.42832272 | T33: =VLOOKUP($A33,'[2]All month (2)'!$E:$Y,8,FALSE) -> 0 | U33: =VLOOKUP($A33,'[2]All month (2)'!$E:$Y,14,FALSE) -> 1846193.8 | V33: =VLOOKUP($A33,'[2]All month (2)'!$E:$Y,20,FALSE) -> 274368.6 | W33: =SUM(T33:V33) -> 2120562.4 | X33: =IFERROR((R33-W33)/W33,100%) -> 0.89614234
A34: Birampur | B34: =VLOOKUP($A34,'Growth Analysis'!A:G,2,FALSE) -> 319.362 | C34: =VLOOKUP(A34,'Growth Analysis'!A:G,4,FALSE) -> -0.79126334 | D34: =IFERROR((C34-B34)/B34,100%) -> -1.0024776 | E34: =VLOOKUP($A34,'Growth Analysis'!$A:$G,5,FALSE) -> 13171001 | F34: =VLOOKUP($A34,'Growth Analysis'!$A:$G,6,FALSE) -> 2638335.7 | G34: =IFERROR((F34-E34)/E34,100%) -> -0.79968602 | H34: =F34/$F$3 -> 0.0014782407 | I34: =E34/$E$3 -> 0.0081869669 | J34: 313.1 | K34: =VLOOKUP($A34,[1]Notes!$A:$G,3,FALSE) -> 3488835.9 | L34: =VLOOKUP($A34,[1]Notes!$A:$G,5,FALSE) -> 2093301.5 | M34: =VLOOKUP($A34,[1]Notes!$A:$G,7,FALSE) -> 2232855 | N34: =SUM(K34:M34) -> 7814992.4 | O34: =$O$3*H34 -> 1995625 | P34: =$P$3*H34 -> 1197375 | Q34: =$Q$3*H34 -> 1277200 | R34: =SUM(O34:Q34) -> 4470200 | S34: =R34/N34-1 -> -0.42799689 | T34: =VLOOKUP($A34,'[2]All month (2)'!$E:$Y,8,FALSE) -> 17626404 | U34: =VLOOKUP($A34,'[2]All month (2)'!$E:$Y,14,FALSE) -> 2143967 | V34: =VLOOKUP($A34,'[2]All month (2)'!$E:$Y,20,FALSE) -> 318621.6 | W34: =SUM(T34:V34) -> 20088993 | X34: =IFERROR((R34-W34)/W34,100%) -> -0.77748013
A35: Nawabganj_Dinajpur | B35: =VLOOKUP($A35,'Growth Analysis'!A:G,2,FALSE) -> 0 | C35: =VLOOKUP(A35,'Growth Analysis'!A:G,4,FALSE) -> 1 | D35: =IFERROR((C35-B35)/B35,100%) -> 1 | E35: =VLOOKUP($A35,'Growth Analysis'!$A:$G,5,FALSE) -> 4932628.2 | F35: =VLOOKUP($A35,'Growth Analysis'!$A:$G,6,FALSE) -> 649509 | G35: =IFERROR((F35-E35)/E35,100%) -> -0.86832395 | H35: =F35/$F$3 -> 0.00036391528 | I35: =E35/$E$3 -> 0.003066074 | J35: 0 | K35: =VLOOKUP($A35,[1]Notes!$A:$G,3,FALSE) -> 8418530.3 | L35: =VLOOKUP($A35,[1]Notes!$A:$G,5,FALSE) -> 5051118.2 | M35: =VLOOKUP($A35,[1]Notes!$A:$G,7,FALSE) -> 5387859.4 | N35: =SUM(K35:M35) -> 18857508 | O35: =$O$3*H35 -> 491285.63 | P35: =$P$3*H35 -> 294771.38 | Q35: =$Q$3*H35 -> 314422.8 | R35: =SUM(O35:Q35) -> 1100479.8 | S35: =R35/N35-1 -> -0.94164235 | T35: =VLOOKUP($A35,'[2]All month (2)'!$E:$Y,8,FALSE) -> 0 | U35: =VLOOKUP($A35,'[2]All month (2)'!$E:$Y,14,FALSE) -> 1995303.1 | V35: =VLOOKUP($A35,'[2]All month (2)'!$E:$Y,20,FALSE) -> 312069.8 | W35: =SUM(T35:V35) -> 2307372.9 | X35: =IFERROR((R35-W35)/W35,100%) -> -0.52305941
A36: Dinajpur Area | B36: =SUM(B28:B35) -> 2602.9885 | C36: =SUM(C28:C35) -> 5.9463878 | D36: =IFERROR((C36-B36)/B36,100%) -> -0.99771555 | E36: =SUM(E28:E35) -> 81239043 | F36: =SUM(F28:F35) -> 68179822 | G36: =IFERROR((F36-E36)/E36,100%) -> -0.16075055 | H36: =F36/$F$3 -> 0.03820067 | I36: =E36/$E$3 -> 0.050497404 | J36: =SUM(J28:J35) -> 2551.9495 | K36: =SUM(K28:K35) -> 57960000 | L36: =SUM(L28:L35) -> 34776000 | M36: =SUM(M28:M35) -> 37094400 | N36: =SUM(K36:M36) -> 129830400 | O36: =$O$3*H36 -> 51570905 | P36: =$P$3*H36 -> 30942543 | Q36: =$Q$3*H36 -> 33005379 | R36: =SUM(O36:Q36) -> 1.1551883e+08 | T36: =SUM(T28:T35) -> 63508484 | U36: =SUM(U28:U35) -> 30582414 | V36: =SUM(V28:V35) -> 40984440 | W36: =SUM(W28:W35) -> 135075338 | X36: =IFERROR((R36-W36)/W36,100%) -> -0.14478225
A37: Dinajpur Zone | B37: =B36+B27+B20+B12 -> 6296.2156 | C37: =C36+C27+C20+C12 -> 15.259101 | D37: =IFERROR((C37-B37)/B37,100%) -> -0.99757646 | E37: =E36+E27+E20+E12 -> 1.8929973e+08 | F37: =F36+F27+F20+F12 -> 1.792486e+08 | G37: =IFERROR((F37-E37)/E37,100%) -> -0.053096379 | H37: =F37/$F$3 -> 0.10043171 | I37: =E37/$E$3 -> 0.11766688 | J37: =J36+J27+J20+J12 -> 6172.7604 | K37: =K36+K27+K20+K12 -> 168360000 | L37: =L36+L27+L20+L12 -> 101016000 | M37: =M36+M27+M20+M12 -> 107750400 | N37: =SUM(K37:M37) -> 377126400 | O37: =$O$3*H37 -> 1.3558282e+08 | P37: =$P$3*H37 -> 81349689 | Q37: =$Q$3*H37 -> 86773002 | R37: =SUM(O37:Q37) -> 3.0370551e+08 | T37: =T36+T27+T20+T12 -> 181572479 | U37: =U36+U27+U20+U12 -> 119988341 | V37: =V36+V27+V20+V12 -> 126598751 | W37: =W36+W27+W20+W12 -> 428159571 | X37: =IFERROR((R37-W37)/W37,100%) -> -0.29067215
A38: Rangpur Sadar | B38: =VLOOKUP($A38,'Growth Analysis'!A:G,2,FALSE) -> 665.36563 | C38: =VLOOKUP(A38,'Growth Analysis'!A:G,4,FALSE) -> -0.90150975 | D38: =IFERROR((C38-B38)/B38,100%) -> -1.0013549 | E38: =VLOOKUP($A38,'Growth Analysis'!$A:$G,5,FALSE) -> 16427208 | F38: =VLOOKUP($A38,'Growth Analysis'!$A:$G,6,FALSE) -> 2725436.7 | G38: =IFERROR((F38-E38)/E38,100%) -> -0.83409009 | H38: =F38/$F$3 -> 0.0015270428 | I38: =E38/$E$3 -> 0.010210994 | J38: 652.31925 | K38: =VLOOKUP($A38,[1]Notes!$A:$G,3,FALSE) -> 5016642.5 | L38: =VLOOKUP($A38,[1]Notes!$A:$G,5,FALSE) -> 3009985.5 | M38: =VLOOKUP($A38,[1]Notes!$A:$G,7,FALSE) -> 3210651.2 | N38: =SUM(K38:M38) -> 11237279 | O38: =$O$3*H38 -> 2061507.8 | P38: =$P$3*H38 -> 1236904.7 | Q38: =$Q$3*H38 -> 1319365 | R38: =SUM(O38:Q38) -> 4617777.4 | S38: =R38/N38-1 -> -0.58906624 | T38: =VLOOKUP($A38,'[2]All month (2)'!$E:$Y,8,FALSE) -> 21885465 | U38: =VLOOKUP($A38,'[2]All month (2)'!$E:$Y,14,FALSE) -> 4981840 | V38: =VLOOKUP($A38,'[2]All month (2)'!$E:$Y,20,FALSE) -> 4902939.7 | W38: =SUM(T38:V38) -> 31770245 | X38: =IFERROR((R38-W38)/W38,100%) -> -0.85465087
A39: Badarganj | B39: =VLOOKUP($A39,'Growth Analysis'!A:G,2,FALSE) -> 0 | C39: =VLOOKUP(A39,'Growth Analysis'!A:G,4,FALSE) -> 1 | D39: =IFERROR((C39-B39)/B39,100%) -> 1 | E39: =VLOOKUP($A39,'Growth Analysis'!$A:$G,5,FALSE) -> 0 | F39: =VLOOKUP($A39,'Growth Analysis'!$A:$G,6,FALSE) -> 2881363.3 | G39: =IFERROR((F39-E39)/E39,100%) -> 1 | H39: =F39/$F$3 -> 0.0016144074 | I39: =E39/$E$3 -> 0 | J39: 0 | K39: =VLOOKUP($A39,[1]Notes!$A:$G,3,FALSE) -> 5016642.5 | L39: =VLOOKUP($A39,[1]Notes!$A:$G,5,FALSE) -> 3009985.5 | M39: =VLOOKUP($A39,[1]Notes!$A:$G,7,FALSE) -> 3210651.2 | N39: =SUM(K39:M39) -> 11237279 | O39: =$O$3*H39 -> 2179450 | P39: =$P$3*H39 -> 1307670 | Q39: =$Q$3*H39 -> 1394848 | R39: =SUM(O39:Q39) -> 4881967.9 | S39: =R39/N39-1 -> -0.56555605 | T39: =VLOOKUP($A39,'[2]All month (2)'!$E:$Y,8,FALSE) -> 0 | U39: =VLOOKUP($A39,'[2]All month (2)'!$E:$Y,14,FALSE) -> 5434734.6 | V39: =VLOOKUP($A39,'[2]All month (2)'!$E:$Y,20,FALSE) -> 5348661.5 | W39: =SUM(T39:V39) -> 10783396 | X39: =IFERROR((R39-W39)/W39,100%) -> -0.5472699
A40: Gangachara | B40: =VLOOKUP($A40,'Growth Analysis'!A:G,2,FALSE) -> 0 | C40: =VLOOKUP(A40,'Growth Analysis'!A:G,4,FALSE) -> 1 | D40: =IFERROR((C40-B40)/B40,100%) -> 1 | E40: =VLOOKUP($A40,'Growth Analysis'!$A:$G,5,FALSE) -> 0 | F40: =VLOOKUP($A40,'Growth Analysis'!$A:$G,6,FALSE) -> 2881363.3 | G40: =IFERROR((F40-E40)/E40,100%) -> 1 | H40: =F40/$F$3 -> 0.0016144074 | I40: =E40/$E$3 -> 0 | J40: 0 | K40: =VLOOKUP($A40,[1]Notes!$A:$G,3,FALSE) -> 5016642.5 | L40: =VLOOKUP($A40,[1]Notes!$A:$G,5,FALSE) -> 3009985.5 | M40: =VLOOKUP($A40,[1]Notes!$A:$G,7,FALSE) -> 3210651.2 | N40: =SUM(K40:M40) -> 11237279 | O40: =$O$3*H40 -> 2179450 | P40: =$P$3*H40 -> 1307670 | Q40: =$Q$3*H40 -> 1394848 | R40: =SUM(O40:Q40) -> 4881967.9 | S40: =R40/N40-1 -> -0.56555605 | T40: =VLOOKUP($A40,'[2]All month (2)'!$E:$Y,8,FALSE) -> 0 | U40: =VLOOKUP($A40,'[2]All month (2)'!$E:$Y,14,FALSE) -> 4679910.3 | V40: =VLOOKUP($A40,'[2]All month (2)'!$E:$Y,20,FALSE) -> 4605791.8 | W40: =SUM(T40:V40) -> 9285702.2 | X40: =IFERROR((R40-W40)/W40,100%) -> -0.47424892
...

Sheet April - Jun (Q2) Delivery Note
A1: Territory | B1: Jan - Mar (Q1) | J1: April - Jun (Q2 - 2026) | N1: April - Jun (Q2 - 2026)
B2: DN | E2: Collection | J2: Target Projected - TP | N2: Target on 2026 Contribution - TOC | S2: April - Jun (Q2 - 2025)
B3: 55197.687 | C3: 36479.581 | D3: =IFERROR((C3-B3)/B3,100%) -> -0.33911033 | E3: 1.6087766e+09 | F3: 1.7847808e+09 | G3: =IFERROR((F3-E3)/E3,100%) -> 0.10940249 | H3: Total | J3: 37500 | K3: 22500 | L3: 24000 | M3: 84000 | N3: 38000 | O3: 24600 | P3: 27000 | Q3: =SUM(N3:P3) -> 89600 | R3: Variance TOC - TP | S3: 25111.232 | T3: 25149.97 | U3: 16790.525 | V3: 67051.727 | W3: =IFERROR((Q3/V3-1),100%) -> 0.33628176
B4: 2025 | C4: 2025 | D4: Growth | E4: 2025 | F4: 2026 | G4: Growth | H4: Contribution 2026 | I4: Contribution 2025 | J4: Apr | K4: May | L4: Jun | M4: Total | N4: Apr | O4: May | P4: Jun | Q4: Total | S4: Apr | T4: May | U4: Jun | V4: Total | W4: Growth
A5: Debiganj | B5: 0 | C5: 218.61453 | D5: =IFERROR((C5-B5)/B5,100%) -> 1 | E5: 0 | F5: 10882606 | G5: =IFERROR((F5-E5)/E5,100%) -> 1 | H5: =C5/$C$3 -> 0.0059927915 | I5: =B5/$B$3 -> 0 | J5: 222.22222 | K5: 133.33333 | L5: 142.22222 | M5: 497.77778 | N5: =$N$3*H5 -> 227.72608 | O5: =$O$3*H5 -> 147.42267 | P5: =$P$3*H5 -> 161.80537 | Q5: =SUM(N5:P5) -> 536.95412 | R5: =M5/Q5-1 -> -0.072960319 | S5: 0 | T5: 323.3 | U5: 231.1675 | V5: =SUM(S5:U5) -> 554.4675 | W5: =IFERROR((Q5-V5)/V5,100%) -> -0.031585941
A6: Boda | B6: 863.54776 | C6: 161.43507 | D6: =IFERROR((C6-B6)/B6,100%) -> -0.813056 | E6: 29967600 | F6: 6965953.7 | G6: =IFERROR((F6-E6)/E6,100%) -> -0.7675505 | H6: =C6/$C$3 -> 0.0044253544 | I6: =B6/$B$3 -> 0.015644637 | J6: 218.25397 | K6: 130.95238 | L6: 139.68254 | M6: 488.88889 | N6: =$N$3*H6 -> 168.16347 | O6: =$O$3*H6 -> 108.86372 | P6: =$P$3*H6 -> 119.48457 | Q6: =SUM(N6:P6) -> 396.51175 | R6: =Q6/M6-1 -> -0.18895323 | S6: 686.27325 | T6: 350.24 | U6: 250.4325 | V6: =SUM(S6:U6) -> 1286.9457 | W6: =IFERROR((Q6-V6)/V6,100%) -> -0.69189707
A7: Tetulia | B7: 0 | C7: 86.578039 | D7: =IFERROR((C7-B7)/B7,100%) -> 1 | E7: 0 | F7: 4737540.8 | G7: =IFERROR((F7-E7)/E7,100%) -> 1 | H7: =C7/$C$3 -> 0.0023733287 | I7: =B7/$B$3 -> 0 | J7: 79.365079 | K7: 47.619048 | L7: 50.793651 | M7: 177.77778 | N7: =$N$3*H7 -> 90.186492 | O7: =$O$3*H7 -> 58.383887 | P7: =$P$3*H7 -> 64.079876 | Q7: =SUM(N7:P7) -> 212.65026 | R7: =Q7/M7-1 -> 0.19615769 | S7: 0 | T7: 90.89 | U7: 59.435 | V7: =SUM(S7:U7) -> 150.325 | W7: =IFERROR((Q7-V7)/V7,100%) -> 0.4146034
A8: Panchagarh Sadar | B8: 382.58925 | C8: 166.62421 | D8: =IFERROR((C8-B8)/B8,100%) -> -0.56448277 | E8: 6759276.8 | F8: 8571373 | G8: =IFERROR((F8-E8)/E8,100%) -> 0.26809025 | H8: =C8/$C$3 -> 0.0045676021 | I8: =B8/$B$3 -> 0.0069312551 | J8: 192.46032 | K8: 115.47619 | L8: 123.1746 | M8: 431.11111 | N8: =$N$3*H8 -> 173.56888 | O8: =$O$3*H8 -> 112.36301 | P8: =$P$3*H8 -> 123.32526 | Q8: =SUM(N8:P8) -> 409.25715 | R8: =Q8/M8-1 -> -0.050692184 | S8: 84.049 | T8: 222.52 | U8: 145.5125 | V8: =SUM(S8:U8) -> 452.0815 | W8: =IFERROR((Q8-V8)/V8,100%) -> -0.094727063
A9: Atwari | B9: 375.10041 | C9: 111.141 | D9: =IFERROR((C9-B9)/B9,100%) -> -0.70370333 | E9: 15849772 | F9: 8071774.4 | G9: =IFERROR((F9-E9)/E9,100%) -> -0.49073246 | H9: =C9/$C$3 -> 0.0030466634 | I9: =B9/$B$3 -> 0.006795582 | J9: 144.84127 | K9: 86.904762 | L9: 92.698413 | M9: 324.44444 | N9: =$N$3*H9 -> 115.77321 | O9: =$O$3*H9 -> 74.947919 | P9: =$P$3*H9 -> 82.259911 | Q9: =SUM(N9:P9) -> 272.98104 | R9: =Q9/M9-1 -> -0.15862009 | S9: 241.478 | T9: 119.07 | U9: 100.7625 | V9: =SUM(S9:U9) -> 461.3105 | W9: =IFERROR((Q9-V9)/V9,100%) -> -0.40824881
A10: Baliadangi | B10: 0 | C10: 86.868626 | D10: =IFERROR((C10-B10)/B10,100%) -> 1 | E10: 405501 | F10: 5615183.4 | G10: =IFERROR((F10-E10)/E10,100%) -> 12.84752 | H10: =C10/$C$3 -> 0.0023812945 | I10: =B10/$B$3 -> 0 | J10: 105.15873 | K10: 63.095238 | L10: 67.301587 | M10: 235.55556 | N10: =$N$3*H10 -> 90.489191 | O10: =$O$3*H10 -> 58.579845 | P10: =$P$3*H10 -> 64.294952 | Q10: =SUM(N10:P10) -> 213.36399 | R10: =Q10/M10-1 -> -0.094209486 | S10: 0 | T10: 81.47 | U10: 68.9425 | V10: =SUM(S10:U10) -> 150.4125 | W10: =IFERROR((Q10-V10)/V10,100%) -> 0.41852564
A11: Ruhia | B11: 0 | C11: 93.15537 | D11: =IFERROR((C11-B11)/B11,100%) -> 1 | E11: 0 | F11: 7678287.9 | G11: =IFERROR((F11-E11)/E11,100%) -> 1 | H11: =C11/$C$3 -> 0.0025536305 | I11: =B11/$B$3 -> 0 | J11: 162.69841 | K11: 97.619048 | L11: 104.12698 | M11: 364.44444 | N11: =$N$3*H11 -> 97.037958 | O11: =$O$3*H11 -> 62.81931 | P11: =$P$3*H11 -> 68.948023 | Q11: =SUM(N11:P11) -> 228.80529 | R11: =Q11/M11-1 -> -0.37218061 | S11: 0 | T11: 112.81 | U11: 95.46 | V11: =SUM(S11:U11) -> 208.27 | W11: =IFERROR((Q11-V11)/V11,100%) -> 0.098599366
A12: Panchagarh Area | B12: 1621.2374 | C12: 924.41685 | D12: =IFERROR((C12-B12)/B12,100%) -> -0.42980785 | E12: 52982150 | F12: 52522719 | G12: =IFERROR((F12-E12)/E12,100%) -> -0.0086714267 | H12: =C12/$C$3 -> 0.025340665 | I12: =B12/$B$3 -> 0.029371474 | J12: 1125 | K12: 675 | L12: 720 | M12: 2520 | N12: =$N$3*H12 -> 962.94527 | O12: =$O$3*H12 -> 623.38036 | P12: =$P$3*H12 -> 684.19796 | Q12: =SUM(N12:P12) -> 2270.5236 | S12: =SUM(S5:S11) -> 1011.8002 | T12: =SUM(T5:T11) -> 1300.3 | U12: =SUM(U5:U11) -> 951.7125 | V12: =SUM(V5:V11) -> 3263.8127 | W12: =IFERROR((Q12-V12)/V12,100%) -> -0.30433399
A13: Pirganj_Thakurgaon | B13: 0 | C13: 77.639814 | D13: =IFERROR((C13-B13)/B13,100%) -> 1 | E13: 812738.04 | F13: 6165818.3 | G13: =IFERROR((F13-E13)/E13,100%) -> 6.5864769 | H13: =C13/$C$3 -> 0.0021283088 | I13: =B13/$B$3 -> 0 | J13: 135 | K13: 81 | L13: 86.4 | M13: 302.4 | N13: =$N$3*H13 -> 80.875735 | O13: =$O$3*H13 -> 52.356397 | P13: =$P$3*H13 -> 57.464338 | Q13: =SUM(N13:P13) -> 190.69647 | R13: =Q13/M13-1 -> -0.36938998 | S13: 0 | T13: 150.88 | U13: 66.2975 | V13: =SUM(S13:U13) -> 217.1775 | W13: =IFERROR((Q13-V13)/V13,100%) -> -0.12193266
A14: Ranisankail | B14: 0 | C14: 118.16876 | D14: =IFERROR((C14-B14)/B14,100%) -> 1 | E14: 0 | F14: 8376159.9 | G14: =IFERROR((F14-E14)/E14,100%) -> 1 | H14: =C14/$C$3 -> 0.0032393125 | I14: =B14/$B$3 -> 0 | J14: 207 | K14: 124.2 | L14: 132.48 | M14: 463.68 | N14: =$N$3*H14 -> 123.09387 | O14: =$O$3*H14 -> 79.687087 | P14: =$P$3*H14 -> 87.461436 | Q14: =SUM(N14:P14) -> 290.2424 | R14: =Q14/M14-1 -> -0.3740459 | S14: 0 | T14: 171.69 | U14: 75.4425 | V14: =SUM(S14:U14) -> 247.1325 | W14: =IFERROR((Q14-V14)/V14,100%) -> 0.17444042
A15: Thakurgaon Sadar | B15: 515.9315 | C15: 119.80646 | D15: =IFERROR((C15-B15)/B15,100%) -> -0.76778611 | E15: 25461030 | F15: 9484805.3 | G15: =IFERROR((F15-E15)/E15,100%) -> -0.62747755 | H15: =C15/$C$3 -> 0.0032842061 | I15: =B15/$B$3 -> 0.0093469768 | J15: 216 | K15: 129.6 | L15: 138.24 | M15: 483.84 | N15: =$N$3*H15 -> 124.79983 | O15: =$O$3*H15 -> 80.79147 | P15: =$P$3*H15 -> 88.673564 | Q15: =SUM(N15:P15) -> 294.26487 | R15: =Q15/M15-1 -> -0.39181369 | S15: 578.64565 | T15: 197.7 | U15: 86.875 | V15: =SUM(S15:U15) -> 863.22065 | W15: =IFERROR((Q15-V15)/V15,100%) -> -0.65910817
A16: Birganj | B16: 0 | C16: 113.72498 | D16: =IFERROR((C16-B16)/B16,100%) -> 1 | E16: 203245.2 | F16: 4186426.7 | G16: =IFERROR((F16-E16)/E16,100%) -> 19.597912 | H16: =C16/$C$3 -> 0.0031174967 | I16: =B16/$B$3 -> 0 | J16: 135 | K16: 81 | L16: 86.4 | M16: 302.4 | N16: =$N$3*H16 -> 118.46488 | O16: =$O$3*H16 -> 76.69042 | P16: =$P$3*H16 -> 84.172412 | Q16: =SUM(N16:P16) -> 279.32771 | R16: =Q16/M16-1 -> -0.076297265 | S16: 385.40395 | T16: 109.29 | U16: 72.4575 | V16: =SUM(S16:U16) -> 567.15145 | W16: =IFERROR((Q16-V16)/V16,100%) -> -0.50749009
A17: Khansama | B17: 0 | C17: 37.851975 | D17: =IFERROR((C17-B17)/B17,100%) -> 1 | E17: 0 | F17: 3429066.9 | G17: =IFERROR((F17-E17)/E17,100%) -> 1 | H17: =C17/$C$3 -> 0.0010376209 | I17: =B17/$B$3 -> 0 | J17: 135 | K17: 81 | L17: 86.4 | M17: 302.4 | N17: =$N$3*H17 -> 39.429593 | O17: =$O$3*H17 -> 25.525474 | P17: =$P$3*H17 -> 28.015764 | Q17: =SUM(N17:P17) -> 92.970831 | R17: =Q17/M17-1 -> -0.69255678 | S17: 0 | T17: 100.18 | U17: 66.42 | V17: =SUM(S17:U17) -> 166.6 | W17: =IFERROR((Q17-V17)/V17,100%) -> -0.4419518
A18: Kaharole | B18: 0 | C18: 28.381894 | D18: =IFERROR((C18-B18)/B18,100%) -> 1 | E18: 0 | F18: 5136695.5 | G18: =IFERROR((F18-E18)/E18,100%) -> 1 | H18: =C18/$C$3 -> 0.00077802137 | I18: =B18/$B$3 -> 0 | J18: 135 | K18: 81 | L18: 86.4 | M18: 302.4 | N18: =$N$3*H18 -> 29.564812 | O18: =$O$3*H18 -> 19.139326 | P18: =$P$3*H18 -> 21.006577 | Q18: =SUM(N18:P18) -> 69.710715 | R18: =Q18/M18-1 -> -0.76947515 | S18: 0 | T18: 122.95 | U18: 81.515 | V18: =SUM(S18:U18) -> 204.465 | W18: =IFERROR((Q18-V18)/V18,100%) -> -0.65905796
A19: Bochaganj | B19: 0 | C19: 135.68717 | D19: =IFERROR((C19-B19)/B19,100%) -> 1 | E19: 391680 | F19: 5416272.8 | G19: =IFERROR((F19-E19)/E19,100%) -> 12.828311 | H19: =C19/$C$3 -> 0.0037195375 | I19: =B19/$B$3 -> 0 | J19: 162 | K19: 97.2 | L19: 103.68 | M19: 362.88 | N19: =$N$3*H19 -> 141.34242 | O19: =$O$3*H19 -> 91.500622 | P19: =$P$3*H19 -> 100.42751 | Q19: =SUM(N19:P19) -> 333.27056 | R19: =Q19/M19-1 -> -0.081595689 | S19: 0 | T19: 122.95 | U19: 81.515 | V19: =SUM(S19:U19) -> 204.465 | W19: =IFERROR((Q19-V19)/V19,100%) -> 0.62996384
A20: Thakurgaon Area | B20: 515.9315 | C20: 631.26105 | D20: =IFERROR((C20-B20)/B20,100%) -> 0.22353655 | E20: 26868693 | F20: 42195245 | G20: =IFERROR((F20-E20)/E20,100%) -> 0.57042418 | H20: =C20/$C$3 -> 0.017304504 | I20: =B20/$B$3 -> 0.0093469768 | J20: 1125 | K20: 675 | L20: 720 | M20: 2520 | N20: =$N$3*H20 -> 657.57114 | O20: =$O$3*H20 -> 425.69079 | P20: =$P$3*H20 -> 467.2216 | Q20: =SUM(N20:P20) -> 1550.4835 | S20: =SUM(S13:S19) -> 964.0496 | T20: =SUM(T13:T19) -> 975.64 | U20: =SUM(U13:U19) -> 530.5225 | V20: =SUM(V13:V19) -> 2470.2121 | W20: =IFERROR((Q20-V20)/V20,100%) -> -0.37232777
A21: Domar | B21: 185.65683 | C21: 12.6651 | D21: =IFERROR((C21-B21)/B21,100%) -> -0.9317822 | E21: 6910500 | F21: 1155000 | G21: =IFERROR((F21-E21)/E21,100%) -> -0.83286303 | H21: =C21/$C$3 -> 0.00034718326 | I21: =B21/$B$3 -> 0.0033634893 | J21: 121.62162 | K21: 72.972973 | L21: 77.837838 | M21: 272.43243 | N21: =$N$3*H21 -> 13.192964 | O21: =$O$3*H21 -> 8.5407083 | P21: =$P$3*H21 -> 9.3739481 | Q21: =SUM(N21:P21) -> 31.10762 | R21: =Q21/M21-1 -> -0.88581528 | S21: 85.111 | T21: 60.24 | U21: 60.8075 | V21: =SUM(S21:U21) -> 206.1585 | W21: =IFERROR((Q21-V21)/V21,100%) -> -0.84910823
A22: Jaldhaka | B22: 0 | C22: 155.64337 | D22: =IFERROR((C22-B22)/B22,100%) -> 1 | E22: 0 | F22: 4006543.8 | G22: =IFERROR((F22-E22)/E22,100%) -> 1 | H22: =C22/$C$3 -> 0.0042665886 | I22: =B22/$B$3 -> 0 | J22: 162.16216 | K22: 97.297297 | L22: 103.78378 | M22: 363.24324 | N22: =$N$3*H22 -> 162.13037 | O22: =$O$3*H22 -> 104.95808 | P22: =$P$3*H22 -> 115.19789 | Q22: =SUM(N22:P22) -> 382.28634 | R22: =Q22/M22-1 -> 0.052425192 | S22: 0 | T22: 124.23 | U22: 64.0625 | V22: =SUM(S22:U22) -> 188.2925 | W22: =IFERROR((Q22-V22)/V22,100%) -> 1.0302792
A23: Nilphamari Sadar | B23: 1370.4014 | C23: 128.16423 | D23: =IFERROR((C23-B23)/B23,100%) -> -0.90647687 | E23: 21299339 | F23: 3415849 | G23: =IFERROR((F23-E23)/E23,100%) -> -0.83962653 | H23: =C23/$C$3 -> 0.0035133141 | I23: =B23/$B$3 -> 0.024827152 | J23: 141.89189 | K23: 85.135135 | L23: 90.810811 | M23: 317.83784 | N23: =$N$3*H23 -> 133.50594 | O23: =$O$3*H23 -> 86.427528 | P23: =$P$3*H23 -> 94.859482 | Q23: =SUM(N23:P23) -> 314.79295 | R23: =Q23/M23-1 -> -0.0095800129 | S23: 521.69 | T23: 240.7 | U23: 124.12 | V23: =SUM(S23:U23) -> 886.51 | W23: =IFERROR((Q23-V23)/V23,100%) -> -0.64490762
A24: Sayedpur | B24: 0 | C24: 89.033799 | D24: =IFERROR((C24-B24)/B24,100%) -> 1 | E24: 0 | F24: 2354295.2 | G24: =IFERROR((F24-E24)/E24,100%) -> 1 | H24: =C24/$C$3 -> 0.0024406475 | I24: =B24/$B$3 -> 0 | J24: 101.35135 | K24: 60.810811 | L24: 64.864865 | M24: 227.02703 | N24: =$N$3*H24 -> 92.744605 | O24: =$O$3*H24 -> 60.039929 | P24: =$P$3*H24 -> 65.897483 | Q24: =SUM(N24:P24) -> 218.68202 | R24: =Q24/M24-1 -> -0.036757786 | S24: 0 | T24: 155.29 | U24: 80.0775 | V24: =SUM(S24:U24) -> 235.3675 | W24: =IFERROR((Q24-V24)/V24,100%) -> -0.070891197
A25: Dimla | B25: 0 | C25: 155.64337 | D25: =IFERROR((C25-B25)/B25,100%) -> 1 | E25: 0 | F25: 4006543.8 | G25: =IFERROR((F25-E25)/E25,100%) -> 1 | H25: =C25/$C$3 -> 0.0042665886 | I25: =B25/$B$3 -> 0 | J25: 162.16216 | K25: 97.297297 | L25: 103.78378 | M25: 363.24324 | N25: =$N$3*H25 -> 162.13037 | O25: =$O$3*H25 -> 104.95808 | P25: =$P$3*H25 -> 115.19789 | Q25: =SUM(N25:P25) -> 382.28634 | R25: =Q25/M25-1 -> 0.052425192 | S25: 0 | T25: 163.05 | U25: 84.0825 | V25: =SUM(S25:U25) -> 247.1325 | W25: =IFERROR((Q25-V25)/V25,100%) -> 0.54688817
A26: Kishoreganj_Nilphamari | B26: 0 | C26: 54.079918 | D26: =IFERROR((C26-B26)/B26,100%) -> 1 | E26: 0 | F26: 1412577.1 | G26: =IFERROR((F26-E26)/E26,100%) -> 1 | H26: =C26/$C$3 -> 0.0014824709 | I26: =B26/$B$3 -> 0 | J26: 60.810811 | K26: 36.486486 | L26: 38.918919 | M26: 136.21622 | N26: =$N$3*H26 -> 56.333895 | O26: =$O$3*H26 -> 36.468785 | P26: =$P$3*H26 -> 40.026715 | Q26: =SUM(N26:P26) -> 132.82939 | R26: =Q26/M26-1 -> -0.024863574 | S26: 0 | T26: 93.17 | U26: 48.0475 | V26: =SUM(S26:U26) -> 141.2175 | W26: =IFERROR((Q26-V26)/V26,100%) -> -0.059398486
A27: Nilphamari Area | B27: 1556.0582 | C27: 595.22978 | D27: =IFERROR((C27-B27)/B27,100%) -> -0.61747589 | E27: 28209839 | F27: 16350809 | G27: =IFERROR((F27-E27)/E27,100%) -> -0.42038631 | H27: =C27/$C$3 -> 0.016316793 | I27: =B27/$B$3 -> 0.028190641 | J27: 750 | K27: 450 | L27: 480 | M27: 1680 | N27: =$N$3*H27 -> 620.03814 | O27: =$O$3*H27 -> 401.39311 | P27: =$P$3*H27 -> 440.55341 | Q27: =SUM(N27:P27) -> 1461.9847 | S27: =SUM(S21:S26) -> 606.801 | T27: =SUM(T21:T26) -> 836.68 | U27: =SUM(U21:U26) -> 461.1975 | V27: =SUM(V21:V26) -> 1904.6785 | W27: =IFERROR((Q27-V27)/V27,100%) -> -0.23242444
A28: Birol | B28: 0 | C28: 373.06109 | D28: =IFERROR((C28-B28)/B28,100%) -> 1 | E28: 0 | F28: 15630806 | G28: =IFERROR((F28-E28)/E28,100%) -> 1 | H28: =C28/$C$3 -> 0.010226573 | I28: =B28/$B$3 -> 0 | J28: 284.41597 | K28: 170.64958 | L28: 182.02622 | M28: 637.09177 | N28: =$N$3*H28 -> 388.60976 | O28: =$O$3*H28 -> 251.57369 | P28: =$P$3*H28 -> 276.11746 | Q28: =SUM(N28:P28) -> 916.30092 | R28: =Q28/M28-1 -> 0.43825577 | S28: 0 | T28: 196.57 | U28: 157.82 | V28: =SUM(S28:U28) -> 354.39 | W28: =IFERROR((Q28-V28)/V28,100%) -> 1.5855722
A29: Chirirbandar | B29: 0 | C29: 360.40071 | D29: =IFERROR((C29-B29)/B29,100%) -> 1 | E29: 357000 | F29: 16050806 | G29: =IFERROR((F29-E29)/E29,100%) -> 43.96024 | H29: =C29/$C$3 -> 0.009879519 | I29: =B29/$B$3 -> 0 | J29: 284.41597 | K29: 170.64958 | L29: 182.02622 | M29: 637.09177 | N29: =$N$3*H29 -> 375.42172 | O29: =$O$3*H29 -> 243.03617 | P29: =$P$3*H29 -> 266.74701 | Q29: =SUM(N29:P29) -> 885.2049 | R29: =Q29/M29-1 -> 0.38944645 | S29: 0 | T29: 170.93 | U29: 137.235 | V29: =SUM(S29:U29) -> 308.165 | W29: =IFERROR((Q29-V29)/V29,100%) -> 1.872503
A30: Dinajpur Sadar | B30: 2222.1154 | C30: 261.83536 | D30: =IFERROR((C30-B30)/B30,100%) -> -0.88216842 | E30: 59488914 | F30: 11595445 | G30: =IFERROR((F30-E30)/E30,100%) -> -0.80508226 | H30: =C30/$C$3 -> 0.0071775867 | I30: =B30/$B$3 -> 0.0402574 | J30: 255.97437 | K30: 153.58462 | L30: 163.8236 | M30: 573.38259 | N30: =$N$3*H30 -> 272.74829 | O30: =$O$3*H30 -> 176.56863 | P30: =$P$3*H30 -> 193.79484 | Q30: =SUM(N30:P30) -> 643.11177 | R30: =M30/Q30-1 -> -0.10842466 | S30: 1227.2622 | T30: 196.57 | U30: 157.82 | V30: =SUM(S30:U30) -> 1581.6522 | W30: =IFERROR((Q30-V30)/V30,100%) -> -0.59339244
A31: Parbatipur | B31: 61.5111 | C31: 222.65908 | D31: =IFERROR((C31-B31)/B31,100%) -> 2.6198196 | E31: 2027760 | F31: 9794030.2 | G31: =IFERROR((F31-E31)/E31,100%) -> 3.8299751 | H31: =C31/$C$3 -> 0.0061036634 | I31: =B31/$B$3 -> 0.0011143782 | J31: 170.64958 | K31: 102.38975 | L31: 109.21573 | M31: 382.25506 | N31: =$N$3*H31 -> 231.93921 | O31: =$O$3*H31 -> 150.15012 | P31: =$P$3*H31 -> 164.79891 | Q31: =SUM(N31:P31) -> 546.88824 | R31: =Q31/M31-1 -> 0.43068933 | S31: 0 | T31: 136.74 | U31: 109.7875 | V31: =SUM(S31:U31) -> 246.5275 | W31: =IFERROR((Q31-V31)/V31,100%) -> 1.2183661
A32: Fulbari_Dinajpur | B32: 0 | C32: 222.65908 | D32: =IFERROR((C32-B32)/B32,100%) -> 1 | E32: 0 | F32: 9447741.3 | G32: =IFERROR((F32-E32)/E32,100%) -> 1 | H32: =C32/$C$3 -> 0.0061036634 | I32: =B32/$B$3 -> 0 | J32: 170.64958 | K32: 102.38975 | L32: 109.21573 | M32: 382.25506 | N32: =$N$3*H32 -> 231.93921 | O32: =$O$3*H32 -> 150.15012 | P32: =$P$3*H32 -> 164.79891 | Q32: =SUM(N32:P32) -> 546.88824 | R32: =Q32/M32-1 -> 0.43068933 | S32: 0 | T32: 153.83 | U32: 123.51 | V32: =SUM(S32:U32) -> 277.34 | W32: =IFERROR((Q32-V32)/V32,100%) -> 0.97190539
